Workbook
Name ____col1: #REF!
Name ____row1: #REF!
Name ____SCC2: #REF!
Name ___col1: #REF!
Name ___row1: #REF!
Name ___SCC2: #REF!
Name __col1: #REF!
Name __row1: #REF!
Name __SCC2: [2]SCC!$C$6:$G$20
Name _4._TURNOVER: #REF!
Name _col1: #REF!
Name _row1: #REF!
Name _SCC2: [4]SCC!$C$6:$G$20
Name A_A_A_Check_Prog: #REF!
Name A_A_Aindirect: #REF!
Name A_A_Pt_Budget: #REF!
Name A_A_REVENUE: #REF!
Name A_Breakfast: #REF!
Name a_Check_Rec_Exp: #REF!
Name A_Creative: #REF!
Name A_EXPENSES_5AA: #REF!
Name A_NEWS: #REF!
Name A_Olympics: #REF!
Name A_PROMOTIONS: #REF!
Name A_Pt_All_Variance: #REF!
Name A_PT_Budget_ALL: #REF!
Name A_PT_Cash: #REF!
Name A_PT_Dept: #REF!
Name A_Pt_Dept_Var: #REF!
Name A_PT_prog_Fcast: #REF!
Name A_PT_prog_Var: #REF!
Name a_PT_REPORT_DEPTS: #REF!
Name A_SALES: #REF!
Name A_Saturday: #REF!
Name A_TECH: #REF!
Name A_X_ADMIN: #REF!
Name AA_check_totals: #REF!
Name AA_E_PROG_CHECK: #REF!
Name AA_END_CHECK: #REF!
Name AA_RECON_FIVEAA: #REF!
Name AA_RECON_PROG: #REF!
Name AAA_PRT_REPORT: #REF!
Name aaaa_Check: #REF!
Name Actual: [5]Actual!$D$16:$AB$73
Name ActualForecast: [6]Data!$B$2:$B$3
Name Adjustment_Label: [7]Matrix!$D$4:$D$9
Name admin: #REF!
Name Agency_Revenue: IF('[8]Agency Revenue Table'!$C$30/'[8]Agency Revenue Table'!$D$30<(0.95),Red,IF('[8]Agency Revenue Table'!$C$30/'[8]Agency Revenue Table'!$D$30>=(1),Green,Yellow))
Name Agency_Revenue: IF('[8]Agency Revenue Table'!$C$30/'[8]Agency Revenue Table'!$D$30<(0.95),Red,IF('[8]Agency Revenue Table'!$C$30/'[8]Agency Revenue Table'!$D$30>=(1),Green,Yellow))
Name AgencyRevenueChtData: OFFSET('[9]Dashboard Data'!$A$12,0,COUNT('[9]Dashboard Data'!$12:$12),1,-36)
Name AgencyShareChtData: OFFSET('[9]Dashboard Data'!$A$14,0,COUNT('[9]Dashboard Data'!$14:$14),1,-36)
Name AgencyShareT1ChtData: OFFSET('[8]Dashboard Data'!$A$18,0,COUNT('[8]Dashboard Data'!$18:$18),1,-36)
Name AgencyShareT2ChtData: OFFSET('[8]Dashboard Data'!$A$19,0,COUNT('[8]Dashboard Data'!$19:$19),1,-36)
Name App: _xlfn.ANCHORARRAY(#REF!)
Name AttribName: #REF!
Name AUR_BMAD_Agency_ChtData: OFFSET('[9]Dashboard Data'!#REF!,0,COUNT('[9]Dashboard Data'!#REF!),1,-36)
Name AUR_BMAD_Direct_ChtData: OFFSET('[9]Dashboard Data'!#REF!,0,COUNT('[9]Dashboard Data'!#REF!),1,-36)
Name AUR_ROS_Agency_ChtData: OFFSET('[9]Dashboard Data'!#REF!,0,COUNT('[9]Dashboard Data'!#REF!),1,-36)
Name AUR_ROS_Direct_ChtData: OFFSET('[9]Dashboard Data'!#REF!,0,COUNT('[9]Dashboard Data'!#REF!),1,-36)
Name base: '[12]TOTAL BUSINESS INPUT'!$DC$1:$DC$6

Sheet Delivered Sales
A2: TimePeriod | B2: Week | L2: TimePeriod | M2: Week
A3: BranchType | B3: Company | L3: BranchType | M3: Company
A4: Sales Order Type | B4: Retail | L4: Sales Order Type | M4: Retail
A5: Division | B5: (Multiple Items) | L5: Division | M5: (Multiple Items)
A7: R-Sales ExGST TY $ | B7: Column Labels | L7: R-Sales ExGST TY $ | M7: Column Labels
B8: AU | E8: Grand Total | F8: NZ (AUD) | M8: AU | O8: Grand Total | S8: =J8+N8+O8 -> #VALUE!
A9: Row Labels | B9: Dropship | C9: In Store | D9: Online | F9: Date week | G9: FX Rate (A$1=NZD) | H9: Instore | I9: Online | J9: Total | L9: Row Labels | M9: freedom QLD Sunshine Coast (C) | N9: Freedom QLD Toowoomba | S9: =J9+N9+O9 -> #VALUE!
A10: 202709 | B10: 521012.63 | C10: 3775579.1 | D10: 665512.6 | E10: 4962104.4 | F10: 45930 | G10: =_xlfn.XLOOKUP(F10,FX!$A$12:$A$910,FX!$B$12:$B$910,"",-1) -> 1.141 | H10: =B10/$G10 -> 456628.07 | I10: =C10/$G10 -> 3309008.9 | J10: =D10/$G10 -> 583271.34 | L10: 202701 | M10: 197317.65 | N10: 3367.47 | O10: 200685.12 | S10: =J10+N10+O10 -> 787323.93
A11: Grand Total | B11: 521012.63 | C11: 3775579.1 | D11: 665512.6 | E11: 4962104.4 | F11: =F10+7 -> 45937 | G11: =_xlfn.XLOOKUP(F11,FX!$A$12:$A$910,FX!$B$12:$B$910,"",-1) -> 1.1347 | H11: =B11/$G11 -> 459163.33 | I11: =C11/$G11 -> 3327380.9 | J11: =D11/$G11 -> 586509.74 | L11: 202702 | M11: 252298.55 | N11: 12455.52 | O11: 264754.07 | S11: =J11+N11+O11 -> 863719.33
F12: =F11+7 -> 45944 | G12: =_xlfn.XLOOKUP(F12,FX!$A$12:$A$910,FX!$B$12:$B$910,"",-1) -> 1.1352 | H12: =B12/$G12 -> 0 | I12: =C12/$G12 -> 0 | J12: =D12/$G12 -> 0 | L12: 202703 | M12: 190684.36 | N12: 19319.74 | O12: 210004.1 | S12: =J12+N12+O12 -> 229323.84
F13: =F12+7 -> 45951 | G13: =_xlfn.XLOOKUP(F13,FX!$A$12:$A$910,FX!$B$12:$B$910,"",-1) -> 1.1351 | H13: =B13/$G13 -> 0 | I13: =C13/$G13 -> 0 | J13: =D13/$G13 -> 0 | L13: 202704 | M13: 212729.83 | N13: 29386.3 | O13: 242116.13 | S13: =J13+N13+O13 -> 271502.43
F14: =F13+7 -> 45958 | G14: =_xlfn.XLOOKUP(F14,FX!$A$12:$A$910,FX!$B$12:$B$910,"",-1) -> 1.1351 | H14: =B14/$G14 -> 0 | I14: =C14/$G14 -> 0 | J14: =D14/$G14 -> 0 | L14: 202705 | M14: 219863.95 | N14: 28677.75 | O14: 248541.7 | S14: =J14+N14+O14 -> 277219.45
F15: =F14+7 -> 45965 | G15: =_xlfn.XLOOKUP(F15,FX!$A$12:$A$910,FX!$B$12:$B$910,"",-1) -> 1.1482 | H15: =B15/$G15 -> 0 | I15: =C15/$G15 -> 0 | J15: =D15/$G15 -> 0 | L15: 202706 | M15: 174475.81 | N15: 14165.04 | O15: 188640.85 | S15: =J15+N15+O15 -> 202805.89
F16: =F15+7 -> 45972 | G16: =_xlfn.XLOOKUP(F16,FX!$A$12:$A$910,FX!$B$12:$B$910,"",-1) -> 1.1569 | H16: =B16/$G16 -> 0 | I16: =C16/$G16 -> 0 | J16: =D16/$G16 -> 0 | L16: 202707 | M16: 166915.37 | N16: 21575.82 | O16: 188491.19 | S16: =J16+N16+O16 -> 210067.01
F17: =F16+7 -> 45979 | G17: =_xlfn.XLOOKUP(F17,FX!$A$12:$A$910,FX!$B$12:$B$910,"",-1) -> 1.1469 | H17: =B17/$G17 -> 0 | I17: =C17/$G17 -> 0 | J17: =D17/$G17 -> 0 | L17: 202708 | M17: 249542.33 | N17: 39138.73 | O17: 288681.06 | S17: =J17+N17+O17 -> 327819.79
F18: =F17+7 -> 45986 | G18: =_xlfn.XLOOKUP(F18,FX!$A$12:$A$910,FX!$B$12:$B$910,"",-1) -> 1.1523 | H18: =B18/$G18 -> 0 | I18: =C18/$G18 -> 0 | J18: =D18/$G18 -> 0 | L18: 202709 | M18: 118467.11 | N18: 23927.23 | O18: 142394.34 | S18: =J18+N18+O18 -> 166321.57
F19: =F18+7 -> 45993 | G19: =_xlfn.XLOOKUP(F19,FX!$A$12:$A$910,FX!$B$12:$B$910,"",-1) -> 1.1441 | H19: =B19/$G19 -> 0 | I19: =C19/$G19 -> 0 | J19: =D19/$G19 -> 0 | L19: Grand Total | M19: 1782295 | N19: 192013.6 | O19: 1974308.6 | S19: =J19+N19+O19 -> 2166322.2
F20: =F19+7 -> 46000 | G20: =_xlfn.XLOOKUP(F20,FX!$A$12:$A$910,FX!$B$12:$B$910,"",-1) -> 1.148 | H20: =B20/$G20 -> 0 | I20: =C20/$G20 -> 0 | J20: =D20/$G20 -> 0 | S20: =J20+N20+O20 -> 0
F21: =F20+7 -> 46007 | G21: =_xlfn.XLOOKUP(F21,FX!$A$12:$A$910,FX!$B$12:$B$910,"",-1) -> 1.1483 | H21: =B21/$G21 -> 0 | I21: =C21/$G21 -> 0 | J21: =D21/$G21 -> 0 | S21: =J21+N21+O21 -> 0
F22: =F21+7 -> 46014 | G22: =_xlfn.XLOOKUP(F22,FX!$A$12:$A$910,FX!$B$12:$B$910,"",-1) -> 1.1469 | H22: =B22/$G22 -> 0 | I22: =C22/$G22 -> 0 | J22: =D22/$G22 -> 0 | S22: =J22+N22+O22 -> 0
F23: =F22+7 -> 46021 | G23: =_xlfn.XLOOKUP(F23,FX!$A$12:$A$910,FX!$B$12:$B$910,"",-1) -> 1.1543 | H23: =B23/$G23 -> 0 | I23: =C23/$G23 -> 0 | J23: =D23/$G23 -> 0 | S23: =J23+N23+O23 -> 0
F24: =F23+7 -> 46028 | G24: =_xlfn.XLOOKUP(F24,FX!$A$12:$A$910,FX!$B$12:$B$910,"",-1) -> 1.1599 | H24: =B24/$G24 -> 0 | I24: =C24/$G24 -> 0 | J24: =D24/$G24 -> 0 | S24: =J24+N24+O24 -> 0
F25: =F24+7 -> 46035 | G25: =_xlfn.XLOOKUP(F25,FX!$A$12:$A$910,FX!$B$12:$B$910,"",-1) -> 1.1613 | H25: =B25/$G25 -> 0 | I25: =C25/$G25 -> 0 | J25: =D25/$G25 -> 0 | S25: =J25+N25+O25 -> 0
F26: =F25+7 -> 46042 | G26: =_xlfn.XLOOKUP(F26,FX!$A$12:$A$910,FX!$B$12:$B$910,"",-1) -> 1.1553 | H26: =B26/$G26 -> 0 | I26: =C26/$G26 -> 0 | J26: =D26/$G26 -> 0 | S26: =J26+N26+O26 -> 0
F27: =F26+7 -> 46049 | G27: =_xlfn.XLOOKUP(F27,FX!$A$12:$A$910,FX!$B$12:$B$910,"",-1) -> 1.1588 | H27: =B27/$G27 -> 0 | I27: =C27/$G27 -> 0 | J27: =D27/$G27 -> 0 | S27: =J27+N27+O27 -> 0
F28: =F27+7 -> 46056 | G28: =_xlfn.XLOOKUP(F28,FX!$A$12:$A$910,FX!$B$12:$B$910,"",-1) -> 1.1616 | H28: =B28/$G28 -> 0 | I28: =C28/$G28 -> 0 | J28: =D28/$G28 -> 0 | S28: =J28+N28+O28 -> 0
F29: =F28+7 -> 46063 | G29: =_xlfn.XLOOKUP(F29,FX!$A$12:$A$910,FX!$B$12:$B$910,"",-1) -> 1.1717 | H29: =B29/$G29 -> 0 | I29: =C29/$G29 -> 0 | J29: =D29/$G29 -> 0 | S29: =J29+N29+O29 -> 0
F30: =F29+7 -> 46070 | G30: =_xlfn.XLOOKUP(F30,FX!$A$12:$A$910,FX!$B$12:$B$910,"",-1) -> 1.1709 | H30: =B30/$G30 -> 0 | I30: =C30/$G30 -> 0 | J30: =D30/$G30 -> 0 | S30: =J30+N30+O30 -> 0
F31: =F30+7 -> 46077 | G31: =_xlfn.XLOOKUP(F31,FX!$A$12:$A$910,FX!$B$12:$B$910,"",-1) -> 1.185 | H31: =B31/$G31 -> 0 | I31: =C31/$G31 -> 0 | J31: =D31/$G31 -> 0 | S31: =J31+N31+O31 -> 0
... F107: =F106+7 -> 46609 | G107: =_xlfn.XLOOKUP(F107,FX!$A$12:$A$910,FX!$B$12:$B$910,"",-1) -> 1.198 | H107: =B107/$G107 -> 0 | I107: =C107/$G107 -> 0 | J107: =D107/$G107 -> 0 | S107: =J107+N107+O107 -> 0
S108: =J108+N108+O108 -> 0
S109: =J109+N109+O109 -> 0
S110: =J110+N110+O110 -> 0
S111: =J111+N111+O111 -> 0
S112: =J112+N112+O112 -> 0
S113: =J113+N113+O113 -> 0
F114: 46202 | S114: =J114+N114+O114 -> 0
F115: 46209 | S115: =J115+N115+O115 -> 0
F116: 46216 | S116: =J116+N116+O116 -> 0
F117: 46223 | S117: =J117+N117+O117 -> 0
...

Sheet Sheet10
A1: CHANNEL | B1: Dropship
A2: TimePeriod | B2: Week
A3: BranchType | B3: Company
A4: Sales Order Type | B4: Retail
A5: Division | B5: (Multiple Items)
B7: Column Labels
B8: AU
A9: Row Labels | B9: R-Sales ExGST TY $ | C9: Gross Margin
A10: 202540 | B10: 1504303.7 | C10: 485581.56 | D10: =C10/B10 -> 0.32279489
A11: 202541 | B11: 537273.71 | C11: 172403.68 | D11: =C11/B11 -> 0.32088613
A12: 202542 | B12: 453544.55 | C12: 131764.49 | D12: =C12/B12 -> 0.2905216
A13: 202543 | B13: 1383803.9 | C13: 390121.25 | D13: =C13/B13 -> 0.28191946
A14: 202544 | B14: 584253.49 | C14: 165424.35 | D14: =C14/B14 -> 0.28313797
A15: 202545 | B15: 525016.2 | C15: 167030.99 | D15: =C15/B15 -> 0.31814445
A16: 202546 | B16: 510337.46 | C16: 201316.66 | D16: =C16/B16 -> 0.39447753
A17: 202547 | B17: 1005855.8 | C17: 305517.44 | D17: =C17/B17 -> 0.30373882
A18: 202548 | B18: 570415.38 | C18: 201005.29 | D18: =C18/B18 -> 0.35238406
A19: 202549 | B19: 847724.33 | C19: 221799.93 | D19: =C19/B19 -> 0.26164158
A20: 202550 | B20: 1088375.6 | C20: 265750.33 | D20: =C20/B20 -> 0.24417152
A21: 202551 | B21: 464285.13 | C21: 166244.91 | D21: =C21/B21 -> 0.35806641
... A61: 202639 | B61: 940046.81 | C61: 326280.72 | D61: =C61/B61 -> 0.34708986
A62: Grand Total | B62: 44469673 | C62: 14511273

Sheet Sheet7
A1: TimePeriod | B1: Week | G1: TimePeriod | H1: Week
A2: BranchType | B2: Company | G2: BranchType | H2: Company
A3: Sales Order Type | B3: Retail | G3: Sales Order Type | H3: Retail
A4: Division | B4: (Multiple Items) | G4: Division | H4: (Multiple Items)
A5: StoreName | B5: (Multiple Items) | G5: StoreName | H5: (Multiple Items)
A7: Delivered Sales Ex GST | B7: Column Labels | G7: Delivered Sales Ex GST | H7: Column Labels
B8: AU | E8: Grand Total | H8: NZ | J8: Grand Total
A9: Row Labels | B9: Dropship | C9: In Store | D9: Online | G9: Row Labels | H9: In Store | I9: Online
A10: 202701 | B10: 1513050.6 | C10: 5353941.4 | D10: 1229677.6 | E10: 8096669.6 | G10: 202701 | H10: 1069527.1 | I10: 172397.77 | J10: 1241924.9
A11: 202702 | B11: 799925.47 | C11: 4823046.5 | D11: 1067559.3 | E11: 6690531.3 | G11: 202702 | H11: 848969.81 | I11: 182189.25 | J11: 1031159.1
A12: 202703 | B12: 732734.73 | C12: 3994818 | D12: 756475.03 | E12: 5484027.7 | G12: 202703 | H12: 1137956.6 | I12: 203157.19 | J12: 1341113.8
A13: 202704 | B13: 1566889.2 | C13: 4008074.5 | D13: 1029213.6 | E13: 6604177.3 | G13: 202704 | H13: 916513.58 | I13: 180862.89 | J13: 1097376.5 | L13: FY27 LFL
A14: 202705 | B14: 814999.2 | C14: 3729983.5 | D14: 668725.68 | E14: 5213708.3 | G14: 202705 | H14: 865369.63 | I14: 158015.72 | J14: 1023385.3 | M14: TY | N14: LY
A15: 202706 | B15: 968526.79 | C15: 4014386.6 | D15: 809359.01 | E15: 5792272.4 | G15: 202706 | H15: 753067.58 | I15: 170016.27 | J15: 923083.85 | L15: 1P | M15: =C17+D17+(H17+I17)/1.2 -> 42989740 | N15: {=C35+D35+(SUM(H35:I35/1.2))} -> 46639991 | O15: =M15/N15-1 -> -0.078264396
A16: 202707 | B16: 642302.78 | C16: 4114387.4 | D16: 856835.39 | E16: 5613525.6 | G16: 202707 | H16: 991351.07 | I16: 190513.36 | J16: 1181864.4 | L16: INC DS | M16: =M15+B17 -> 50028169 | N16: =N15+B35 -> 52138524 | O16: =M16/N16-1 -> -0.040475924
A17: Grand Total | B17: 7038428.8 | C17: 30038638 | D17: 6417845.6 | E17: 43494912 | G17: Grand Total | H17: 6582755.4 | I17: 1257152.4 | J17: 7839907.8
A20: TimePeriod | B20: Week | G20: TimePeriod | H20: Week
A21: BranchType | B21: Company | G21: BranchType | H21: Company
A22: Sales Order Type | B22: Retail | G22: Sales Order Type | H22: Retail
A23: Division | B23: (Multiple Items) | G23: Division | H23: (Multiple Items)
A25: R-Sales ExGST LY $ | B25: Column Labels | G25: R-Sales ExGST LY $ | H25: Column Labels
B26: AU | E26: Grand Total | H26: NZ | J26: Grand Total
A27: Row Labels | B27: Dropship | C27: In Store | D27: Online | G27: Row Labels | H27: In Store | I27: Online
A28: 202701 | B28: 1504303.7 | C28: 5530942 | D28: 1856459.7 | E28: 8891705.5 | G28: 202701 | H28: 881173.87 | I28: 220639.44 | J28: 1101813.3
A29: 202702 | B29: 537273.71 | C29: 4932482.5 | D29: 1089777.1 | E29: 6559533.3 | G29: 202702 | H29: 881966.07 | I29: 151835.83 | J29: 1033801.9
A30: 202703 | B30: 453544.55 | C30: 4735388.5 | D30: 800089.43 | E30: 5989022.5 | G30: 202703 | H30: 1018296.1 | I30: 156385.22 | J30: 1174681.3
A31: 202704 | B31: 1383803.9 | C31: 4441078.3 | D31: 1061234.9 | E31: 6886117.2 | G31: 202704 | H31: 861657.55 | I31: 185048.71 | J31: 1046706.3
A32: 202705 | B32: 584253.49 | C32: 4648652.1 | D32: 882425.59 | E32: 6115331.2 | G32: 202705 | H32: 954050.5 | I32: 186389.89 | J32: 1140440.4
A33: 202706 | B33: 525016.2 | C33: 4498420 | D33: 848415.97 | E33: 5871852.2 | G33: 202706 | H33: 962802.76 | I33: 124893.09 | J33: 1087695.9
A34: 202707 | B34: 510337.46 | C34: 4282235.4 | D34: 684220.35 | E34: 5476793.2 | G34: 202707 | H34: 915268.26 | I34: 117395.12 | J34: 1032663.4
B35: =SUM(B28:B39) -> 5498533.1 | C35: =SUM(C28:C39) -> 33069199 | D35: =SUM(D28:D39) -> 7222623.1 | E35: =SUM(E28:E39) -> 45790355 | G35: =SUM(G28:G40) -> 0 | H35: =SUM(H28:H40) -> 6475215.1 | I35: =SUM(I28:I40) -> 1142587.3 | J35: =SUM(J28:J40) -> 7617802.4
B37: =B17/B35-1 -> 0.28005574 | C37: =C17/C35-1 -> -0.091643013 | D37: =D17/D35-1 -> -0.11142455 | E37: =E17/E35-1 -> -0.050129396 | H37: =#REF!/H35-1 -> -1 | I37: =#REF!/I35-1 -> -1 | J37: =#REF!/J35-1 -> -1

Sheet Sheet2
A2: TimePeriod | B2: Week | L2: TimePeriod | M2: Week
A3: BranchType | B3: Company | L3: BranchType | M3: Company
A4: Sales Order Type | B4: Retail | L4: Sales Order Type | M4: Retail
A5: Division | B5: (Multiple Items) | L5: Division | M5: (Multiple Items)
A7: R-Trading Margin TY $ | B7: Column Labels | L7: R-Trading Margin TY $ | M7: Column Labels
B8: NZ | D8: Grand Total | F8: NZ (AUD) | M8: AU | P8: Grand Total | S8: =J8+N8+O8 -> 0
A9: Row Labels | B9: In Store | C9: Online | F9: Date week | G9: FX Rate (A$1=NZD) | H9: Instore | I9: Online | J9: Total | L9: Row Labels | M9: Dropship | N9: In Store | O9: Online | S9: =J9+N9+O9 -> #VALUE!
A10: 202414 | B10: 337979.32 | C10: 109698.59 | D10: 447677.91 | F10: 45930 | G10: =_xlfn.XLOOKUP(F10,FX!$A$12:$A$910,FX!$B$12:$B$910,"",-1) -> 1.141 | H10: =B10/$G10 -> 296213.25 | I10: =C10/$G10 -> 96142.498 | J10: =D10/$G10 -> 392355.75 | L10: 202501 | M10: 81333.86 | N10: 2228562.9 | O10: 364959.9 | P10: 2674856.6 | S10: =J10+N10+O10 -> 2985878.5
A11: 202415 | B11: 374763.9 | C11: 101935.21 | D11: 476699.11 | F11: =F10+7 -> 45937 | G11: =_xlfn.XLOOKUP(F11,FX!$A$12:$A$910,FX!$B$12:$B$910,"",-1) -> 1.1347 | H11: =B11/$G11 -> 330275.76 | I11: =C11/$G11 -> 89834.503 | J11: =D11/$G11 -> 420110.26 | L11: 202502 | M11: 151408.58 | N11: 2691024.2 | O11: 468288.49 | P11: 3310721.3 | S11: =J11+N11+O11 -> 3579423
A12: 202416 | B12: 432751.53 | C12: 86616.75 | D12: 519368.28 | F12: =F11+7 -> 45944 | G12: =_xlfn.XLOOKUP(F12,FX!$A$12:$A$910,FX!$B$12:$B$910,"",-1) -> 1.1352 | H12: =B12/$G12 -> 381211.71 | I12: =C12/$G12 -> 76300.872 | J12: =D12/$G12 -> 457512.58 | L12: 202503 | M12: 144117.9 | N12: 2954724.3 | O12: 515157.13 | P12: 3613999.4 | S12: =J12+N12+O12 -> 3927394
A13: 202417 | B13: 447675.34 | C13: 72449.55 | D13: 520124.89 | F13: =F12+7 -> 45951 | G13: =_xlfn.XLOOKUP(F13,FX!$A$12:$A$910,FX!$B$12:$B$910,"",-1) -> 1.1351 | H13: =B13/$G13 -> 394392.86 | I13: =C13/$G13 -> 63826.579 | J13: =D13/$G13 -> 458219.44 | L13: 202504 | M13: 137957.96 | N13: 2879006.4 | O13: 569604.83 | P13: 3586569.2 | S13: =J13+N13+O13 -> 3906830.7
A14: 202418 | B14: 446872.92 | C14: 108454.53 | D14: 555327.45 | F14: =F13+7 -> 45958 | G14: =_xlfn.XLOOKUP(F14,FX!$A$12:$A$910,FX!$B$12:$B$910,"",-1) -> 1.1351 | H14: =B14/$G14 -> 393685.95 | I14: =C14/$G14 -> 95546.234 | J14: =D14/$G14 -> 489232.18 | L14: 202505 | M14: 193317.4 | N14: 2753752.8 | O14: 618573.74 | P14: 3565643.9 | S14: =J14+N14+O14 -> 3861558.7
A15: 202419 | B15: 546359.89 | C15: 176609.81 | D15: 722969.7 | F15: =F14+7 -> 45965 | G15: =_xlfn.XLOOKUP(F15,FX!$A$12:$A$910,FX!$B$12:$B$910,"",-1) -> 1.1482 | H15: =B15/$G15 -> 475840.35 | I15: =C15/$G15 -> 153814.5 | J15: =D15/$G15 -> 629654.85 | L15: 202506 | M15: 151981.06 | N15: 2830302.8 | O15: 574587.9 | P15: 3556871.8 | S15: =J15+N15+O15 -> 4034545.5
A16: 202420 | B16: 645913.86 | C16: 187115.02 | D16: 833028.88 | F16: =F15+7 -> 45972 | G16: =_xlfn.XLOOKUP(F16,FX!$A$12:$A$910,FX!$B$12:$B$910,"",-1) -> 1.1569 | H16: =B16/$G16 -> 558314.34 | I16: =C16/$G16 -> 161738.28 | J16: =D16/$G16 -> 720052.62 | L16: 202507 | M16: 242677.57 | N16: 3082859.9 | O16: 696551.37 | P16: 4022088.8 | S16: =J16+N16+O16 -> 4499463.9
A17: 202421 | B17: 625948.15 | C17: 171441.89 | D17: 797390.04 | F17: =F16+7 -> 45979 | G17: =_xlfn.XLOOKUP(F17,FX!$A$12:$A$910,FX!$B$12:$B$910,"",-1) -> 1.1469 | H17: =B17/$G17 -> 545773.96 | I17: =C17/$G17 -> 149482.86 | J17: =D17/$G17 -> 695256.81 | L17: 202508 | M17: 240857.59 | N17: 3191169.4 | O17: 528650.26 | P17: 3960677.3 | S17: =J17+N17+O17 -> 4415076.5
A18: 202422 | B18: 632231.33 | C18: 150950.45 | D18: 783181.78 | F18: =F17+7 -> 45986 | G18: =_xlfn.XLOOKUP(F18,FX!$A$12:$A$910,FX!$B$12:$B$910,"",-1) -> 1.1523 | H18: =B18/$G18 -> 548669.04 | I18: =C18/$G18 -> 130999.26 | J18: =D18/$G18 -> 679668.3 | L18: 202509 | M18: 313520.81 | N18: 3169507 | O18: 749573.49 | P18: 4232601.3 | S18: =J18+N18+O18 -> 4598748.8
A19: 202423 | B19: 621172.68 | C19: 163308.6 | D19: 784481.28 | F19: =F18+7 -> 45993 | G19: =_xlfn.XLOOKUP(F19,FX!$A$12:$A$910,FX!$B$12:$B$910,"",-1) -> 1.1441 | H19: =B19/$G19 -> 542935.65 | I19: =C19/$G19 -> 142739.8 | J19: =D19/$G19 -> 685675.45 | L19: 202510 | M19: 364493.1 | N19: 2629342.5 | O19: 822429.05 | P19: 3816264.7 | S19: =J19+N19+O19 -> 4137447
A20: 202424 | B20: 564295.47 | C20: 120867.52 | D20: 685162.99 | F20: =F19+7 -> 46000 | G20: =_xlfn.XLOOKUP(F20,FX!$A$12:$A$910,FX!$B$12:$B$910,"",-1) -> 1.148 | H20: =B20/$G20 -> 491546.58 | I20: =C20/$G20 -> 105285.3 | J20: =D20/$G20 -> 596831.87 | L20: 202511 | M20: 390445.63 | N20: 4593274.8 | O20: 1625702.1 | P20: 6609422.6 | S20: =J20+N20+O20 -> 6815808.8
A21: 202425 | B21: 699732.95 | C21: 133382.87 | D21: 833115.82 | F21: =F20+7 -> 46007 | G21: =_xlfn.XLOOKUP(F21,FX!$A$12:$A$910,FX!$B$12:$B$910,"",-1) -> 1.1483 | H21: =B21/$G21 -> 609364.23 | I21: =C21/$G21 -> 116156.81 | J21: =D21/$G21 -> 725521.05 | L21: 202512 | M21: 158636.36 | N21: 4691391.9 | O21: 1011688 | P21: 5861716.2 | S21: =J21+N21+O21 -> 6428600.9
A22: 202426 | B22: 521540.09 | C22: 137248.46 | D22: 658788.55 | F22: =F21+7 -> 46014 | G22: =_xlfn.XLOOKUP(F22,FX!$A$12:$A$910,FX!$B$12:$B$910,"",-1) -> 1.1469 | H22: =B22/$G22 -> 454738.94 | I22: =C22/$G22 -> 119669.07 | J22: =D22/$G22 -> 574408.01 | L22: 202513 | M22: 54727.25 | N22: 2590362.4 | O22: 446573.21 | P22: 3091662.9 | S22: =J22+N22+O22 -> 3611343.6
... A107: 202607 | B107: 553676.59 | C107: 107492.68 | D107: 661169.27 | F107: =F106+7 -> 46609 | G107: =_xlfn.XLOOKUP(F107,FX!$A$12:$A$910,FX!$B$12:$B$910,"",-1) -> 1.198 | H107: =B107/$G107 -> 462167.44 | I107: =C107/$G107 -> 89726.778 | J107: =D107/$G107 -> 551894.22 | L107: 202707 | M107: 174129.04 | N107: 1574906.9 | O107: 347012.58 | P107: 2096048.5 | S107: =J107+N107+O107 -> 2473813.6
A108: 202608 | B108: 571194.19 | C108: 116873.41 | D108: 688067.6 | L108: Grand Total | M108: 25139672 | N108: 2.6790259e+08 | O108: 57389867 | P108: 3.5043213e+08 | S108: =J108+N108+O108 -> 3.2529246e+08
A109: 202609 | B109: 776922.38 | C109: 206751.94 | D109: 983674.32 | S109: =J109+N109+O109 -> 0
A110: 202610 | B110: 672689.68 | C110: 223997.64 | D110: 896687.32 | S110: =J110+N110+O110 -> 0
A111: 202611 | B111: 1089424.6 | C111: 237022.85 | D111: 1326447.4 | S111: =J111+N111+O111 -> 0
A112: 202612 | B112: 862975.18 | C112: 167319.7 | D112: 1030294.9 | S112: =J112+N112+O112 -> 0
A113: 202613 | B113: 468960.23 | C113: 92406.98 | D113: 561367.21 | S113: =J113+N113+O113 -> 0
A114: 202614 | B114: 400194.15 | C114: 60846.82 | D114: 461040.97 | F114: 46202 | S114: =J114+N114+O114 -> 0
A115: 202615 | B115: 665348.88 | C115: 109027.63 | D115: 774376.51 | F115: 46209 | S115: =J115+N115+O115 -> 0
A116: 202616 | B116: 559188.2 | C116: 88084.55 | D116: 647272.75 | F116: 46216 | S116: =J116+N116+O116 -> 0
A117: 202617 | B117: 642606.02 | C117: 113653.18 | D117: 756259.2 | F117: 46223 | S117: =J117+N117+O117 -> 0
A118: 202618 | B118: 611465.46 | C118: 105923.22 | D118: 717388.68 | F118: 46230 | S118: =J118+N118+O118 -> 0
A119: 202619 | B119: 376454.41 | C119: 65304.66 | D119: 441759.07 | F119: 46237 | S119: =J119+N119+O119 -> 0
A120: 202620 | B120: 524485.76 | C120: 97601.43 | D120: 622087.19 | F120: 46244 | S120: =J120+N120+O120 -> 0
A121: 202621 | B121: 533975.28 | C121: 105676.7 | D121: 639651.98 | S121: =J121+N121+O121 -> 0
A122: 202622 | B122: 495095.58 | C122: 87834.72 | D122: 582930.3 | S122: =J122+N122+O122 -> 0
A123: 202623 | B123: 530780.88 | C123: 82713.89 | D123: 613494.77 | S123: =J123+N123+O123 -> 0
A124: 202624 | B124: 582481.52 | C124: 73907.52 | D124: 656389.04 | S124: =J124+N124+O124 -> 0
A125: 202625 | B125: 571471.11 | C125: 115874.98 | D125: 687346.09 | S125: =J125+N125+O125 -> 0
A126: 202626 | B126: 454765 | C126: 86775.44 | D126: 541540.44 | S126: =J126+N126+O126 -> 0
...

Sheet Written Sales
A1: TimePeriod | B1: WEEK | L1: TimePeriod | M1: WEEK
A2: Branch_Type | B2: Company | L2: Branch_Type | M2: Company
A3: Division | B3: (Multiple Items) | L3: Division | M3: (Multiple Items)
A4: Country | B4: NZ | L4: Country | M4: AU
A6: R-Sales TY $ | B6: Channel | F6: NZ (AUD) | L6: R-Sales TY $ | M6: Channel
A7: Fin_Period | B7: In Store | C7: Online | D7: Grand Total | F7: Date week | G7: FX Rate (A$1=NZD) | H7: Instore | I7: Online | J7: Total | L7: Fin_Period | M7: Dropship | N7: In Store | O7: Online | Q7: Grand Total
A8: 202401 | B8: 752661.48 | C8: 135579.69 | D8: 888241.17 | F8: 45566 | G8: =_xlfn.XLOOKUP(F8,FX!$A$12:$A$910,FX!$B$12:$B$910,"",-1) -> 1.0938 | H8: =B8/$G8 -> 688116.18 | I8: =C8/$G8 -> 123952.9 | J8: =H8+I8 -> 812069.09 | L8: 202401 | M8: 376905.36 | N8: 6851992.3 | O8: 2155136.6 | P8: 0 | Q8: 9384034.2 | S8: =J8+N8+O8 -> 9819197.9
A9: 202402 | B9: 715966.69 | C9: 130560.11 | D9: 846526.79 | F9: =F8+7 -> 45573 | G9: =_xlfn.XLOOKUP(F9,FX!$A$12:$A$910,FX!$B$12:$B$910,"",-1) -> 1.1001 | H9: =B9/$G9 -> 650819.64 | I9: =C9/$G9 -> 118680.22 | J9: =H9+I9 -> 769499.86 | L9: 202402 | M9: 138197.55 | N9: 3523042.4 | O9: 487672.03 | P9: 0 | Q9: 4148912 | S9: =J9+N9+O9 -> 4780214.3
A10: 202403 | B10: 1275011.2 | C10: 552402.54 | D10: 1827413.8 | F10: =F9+7 -> 45580 | G10: =_xlfn.XLOOKUP(F10,FX!$A$12:$A$910,FX!$B$12:$B$910,"",-1) -> 1.1031 | H10: =B10/$G10 -> 1155843.7 | I10: =C10/$G10 -> 500772.86 | J10: =H10+I10 -> 1656616.6 | L10: 202403 | M10: 141073.46 | N10: 3877218.2 | O10: 622969.5 | P10: 0 | Q10: 4641261.1 | S10: =J10+N10+O10 -> 6156804.3
A11: 202404 | B11: 1066632.9 | C11: 177754.23 | D11: 1244387.1 | F11: =F10+7 -> 45587 | G11: =_xlfn.XLOOKUP(F11,FX!$A$12:$A$910,FX!$B$12:$B$910,"",-1) -> 1.104 | H11: =B11/$G11 -> 966152.97 | I11: =C11/$G11 -> 161009.27 | J11: =H11+I11 -> 1127162.2 | L11: 202404 | M11: 242571.17 | N11: 5286957.8 | O11: 843955.33 | P11: 0 | Q11: 6373484.3 | S11: =J11+N11+O11 -> 7258075.4
A12: 202405 | B12: 1085377.2 | C12: 143914.58 | D12: 1229291.8 | F12: =F11+7 -> 45594 | G12: =_xlfn.XLOOKUP(F12,FX!$A$12:$A$910,FX!$B$12:$B$910,"",-1) -> 1.0993 | H12: =B12/$G12 -> 987334.86 | I12: =C12/$G12 -> 130914.75 | J12: =H12+I12 -> 1118249.6 | L12: 202405 | M12: 268468.51 | N12: 5772565.3 | O12: 1136353.3 | P12: 0 | Q12: 7177387.1 | S12: =J12+N12+O12 -> 8027168.2
A13: 202406 | B13: 1030115.2 | C13: 233626.62 | D13: 1263741.8 | F13: =F12+7 -> 45601 | G13: =_xlfn.XLOOKUP(F13,FX!$A$12:$A$910,FX!$B$12:$B$910,"",-1) -> 1.103 | H13: =B13/$G13 -> 933921.32 | I13: =C13/$G13 -> 211810.17 | J13: =H13+I13 -> 1145731.5 | L13: 202406 | M13: 349721.11 | N13: 5676214.2 | O13: 1094373.2 | P13: 0 | Q13: 7120308.5 | S13: =J13+N13+O13 -> 7916318.9
A14: 202407 | B14: 875565.9 | C14: 220143.84 | D14: 1095709.7 | F14: =F13+7 -> 45608 | G14: =_xlfn.XLOOKUP(F14,FX!$A$12:$A$910,FX!$B$12:$B$910,"",-1) -> 1.1 | H14: =B14/$G14 -> 795969 | I14: =C14/$G14 -> 200130.76 | J14: =H14+I14 -> 996099.76 | L14: 202407 | M14: 265584.27 | N14: 4320967.4 | O14: 869353.63 | P14: 0 | Q14: 5455905.3 | S14: =J14+N14+O14 -> 6186420.8
A15: 202408 | B15: 2310550.1 | C15: 888582.85 | D15: 3199133 | F15: =F14+7 -> 45615 | G15: =_xlfn.XLOOKUP(F15,FX!$A$12:$A$910,FX!$B$12:$B$910,"",-1) -> 1.1055 | H15: =B15/$G15 -> 2090049.9 | I15: =C15/$G15 -> 803783.67 | J15: =H15+I15 -> 2893833.5 | L15: 202408 | M15: 370461.47 | N15: 12389582 | O15: 3860922.4 | P15: 0 | Q15: 16620965 | S15: =J15+N15+O15 -> 19144337
A16: 202409 | B16: 1189721.5 | C16: 450742.45 | D16: 1640464 | F16: =F15+7 -> 45622 | G16: =_xlfn.XLOOKUP(F16,FX!$A$12:$A$910,FX!$B$12:$B$910,"",-1) -> 1.1116 | H16: =B16/$G16 -> 1070278.4 | I16: =C16/$G16 -> 405489.79 | J16: =H16+I16 -> 1475768.2 | L16: 202409 | M16: 303091.63 | N16: 6005461.4 | O16: 2231137.4 | P16: 0 | Q16: 8539690.5 | S16: =J16+N16+O16 -> 9712367.1
A17: 202410 | B17: 487221.89 | C17: 169174.06 | D17: 656395.95 | F17: =F16+7 -> 45629 | G17: =_xlfn.XLOOKUP(F17,FX!$A$12:$A$910,FX!$B$12:$B$910,"",-1) -> 1.1011 | H17: =B17/$G17 -> 442486.51 | I17: =C17/$G17 -> 153640.96 | J17: =H17+I17 -> 596127.47 | L17: 202410 | M17: 145182.65 | N17: 3073912.9 | O17: 601991.76 | P17: 0 | Q17: 3821087.3 | S17: =J17+N17+O17 -> 4272032.1
A18: 202411 | B18: 632798.65 | C18: 157528.35 | D18: 790327 | F18: =F17+7 -> 45636 | G18: =_xlfn.XLOOKUP(F18,FX!$A$12:$A$910,FX!$B$12:$B$910,"",-1) -> 1.0958 | H18: =B18/$G18 -> 577476.41 | I18: =C18/$G18 -> 143756.48 | J18: =H18+I18 -> 721232.89 | L18: 202411 | M18: 136993.8 | N18: 3264059.8 | O18: 586222.72 | P18: 0 | Q18: 3987276.3 | S18: =J18+N18+O18 -> 4571515.4
A19: 202412 | B19: 858551.77 | C19: 165909.71 | D19: 1024461.5 | F19: =F18+7 -> 45643 | G19: =_xlfn.XLOOKUP(F19,FX!$A$12:$A$910,FX!$B$12:$B$910,"",-1) -> 1.1018 | H19: =B19/$G19 -> 779226.51 | I19: =C19/$G19 -> 150580.6 | J19: =H19+I19 -> 929807.11 | L19: 202412 | M19: 172183.66 | N19: 4131597.5 | O19: 883862.86 | P19: 0 | Q19: 5187644 | S19: =J19+N19+O19 -> 5945267.4
A20: 202413 | B20: 1493259.9 | C20: 408626.69 | D20: 1901886.6 | F20: =F19+7 -> 45650 | G20: =_xlfn.XLOOKUP(F20,FX!$A$12:$A$910,FX!$B$12:$B$910,"",-1) -> 1.1054 | H20: =B20/$G20 -> 1350877.4 | I20: =C20/$G20 -> 369664.1 | J20: =H20+I20 -> 1720541.5 | L20: 202413 | M20: 472899.16 | N20: 9467931.7 | O20: 2540040.2 | P20: 0 | Q20: 12480871 | S20: =J20+N20+O20 -> 13728513
... A59: 202452 | B59: 627717.44 | C59: 132290.89 | D59: 760008.33 | F59: =F58+7 -> 45923 | G59: =_xlfn.XLOOKUP(F59,FX!$A$12:$A$910,FX!$B$12:$B$910,"",-1) -> 1.1259 | H59: =B59/$G59 -> 557525.04 | I59: =C59/$G59 -> 117497.91 | J59: =H59+I59 -> 675022.95 | L59: 202452 | M59: 411074.67 | N59: 3998323.6 | O59: 572565.54 | P59: 0 | Q59: 4981963.8 | S59: =J59+N59+O59 -> 5245912.1
A60: 202501 | B60: 770748.5 | C60: 106861.91 | D60: 877610.4 | F60: =F59+7 -> 45930 | G60: =_xlfn.XLOOKUP(F60,FX!$A$12:$A$910,FX!$B$12:$B$910,"",-1) -> 1.141 | H60: =B60/$G60 -> 675502.63 | I60: =C60/$G60 -> 93656.36 | J60: =H60+I60 -> 769158.99 | L60: 202501 | M60: 431537.96 | N60: 4388629.3 | O60: 660083.6 | Q60: 5480250.9 | S60: =J60+N60+O60 -> 5817871.9
A61: 202502 | B61: 822827.1 | C61: 172356.48 | D61: 995183.58 | F61: =F60+7 -> 45937 | G61: =_xlfn.XLOOKUP(F61,FX!$A$12:$A$910,FX!$B$12:$B$910,"",-1) -> 1.1347 | H61: =B61/$G61 -> 725149.47 | I61: =C61/$G61 -> 151896.08 | J61: =H61+I61 -> 877045.54 | L61: 202502 | M61: 496870.92 | N61: 4583915.1 | O61: 864820.33 | Q61: 5945606.4 | S61: =J61+N61+O61 -> 6325781
A62: 202503 | B62: 762108.15 | C62: 125729.37 | D62: 887837.51 | F62: =F61+7 -> 45944 | G62: =_xlfn.XLOOKUP(F62,FX!$A$12:$A$910,FX!$B$12:$B$910,"",-1) -> 1.1352 | H62: =B62/$G62 -> 671342.62 | I62: =C62/$G62 -> 110755.25 | J62: =H62+I62 -> 782097.88 | L62: 202503 | M62: 382413.25 | N62: 3952360.6 | O62: 734055.84 | Q62: 5068829.7 | S62: =J62+N62+O62 -> 5468514.3
A63: 202504 | B63: 1217440.9 | C63: 269387.45 | D63: 1486828.4 | F63: =F62+7 -> 45951 | G63: =_xlfn.XLOOKUP(F63,FX!$A$12:$A$910,FX!$B$12:$B$910,"",-1) -> 1.1351 | H63: =B63/$G63 -> 1072540.7 | I63: =C63/$G63 -> 237324.87 | J63: =H63+I63 -> 1309865.6 | L63: 202504 | M63: 695779.86 | N63: 6951189.2 | O63: 1422808.7 | Q63: 9069777.8 | S63: =J63+N63+O63 -> 9683863.5
A64: 202505 | B64: 1029038.2 | C64: 241426.11 | D64: 1270464.3 | F64: =F63+7 -> 45958 | G64: =_xlfn.XLOOKUP(F64,FX!$A$12:$A$910,FX!$B$12:$B$910,"",-1) -> 1.1351 | H64: =B64/$G64 -> 906561.69 | I64: =C64/$G64 -> 212691.49 | J64: =H64+I64 -> 1119253.2 | L64: 202505 | M64: 533868.95 | N64: 4886511.6 | O64: 1208223.4 | Q64: 6628604 | S64: =J64+N64+O64 -> 7213988.2
A65: 202506 | B65: 759011.28 | C65: 144294.47 | D65: 903305.75 | F65: =F64+7 -> 45965 | G65: =_xlfn.XLOOKUP(F65,FX!$A$12:$A$910,FX!$B$12:$B$910,"",-1) -> 1.1482 | H65: =B65/$G65 -> 661044.49 | I65: =C65/$G65 -> 125670.15 | J65: =H65+I65 -> 786714.64 | L65: 202506 | M65: 552401.85 | N65: 4722660.4 | O65: 929385.23 | Q65: 6204447.5 | S65: =J65+N65+O65 -> 6438760.3
A66: 202507 | B66: 774112.63 | C66: 168172.87 | D66: 942285.5 | F66: =F65+7 -> 45972 | G66: =_xlfn.XLOOKUP(F66,FX!$A$12:$A$910,FX!$B$12:$B$910,"",-1) -> 1.1569 | H66: =B66/$G66 -> 669126.66 | I66: =C66/$G66 -> 145365.09 | J66: =H66+I66 -> 814491.75 | L66: 202507 | M66: 698777.42 | N66: 4453606.6 | O66: 811783.19 | Q66: 5964167.2 | S66: =J66+N66+O66 -> 6079881.5
A67: 202508 | B67: 1145270.9 | C67: 187443.5 | D67: 1332714.4 | F67: =F66+7 -> 45979 | G67: =_xlfn.XLOOKUP(F67,FX!$A$12:$A$910,FX!$B$12:$B$910,"",-1) -> 1.1469 | H67: =B67/$G67 -> 998579.54 | I67: =C67/$G67 -> 163434.91 | J67: =H67+I67 -> 1162014.4 | L67: 202508 | M67: 755703.23 | N67: 4768905.4 | O67: 910188.72 | Q67: 6434797.3 | S67: =J67+N67+O67 -> 6841108.5
A68: 202509 | B68: 2582699.1 | C68: 583520.27 | D68: 3166219.4 | F68: =F67+7 -> 45986 | G68: =_xlfn.XLOOKUP(F68,FX!$A$12:$A$910,FX!$B$12:$B$910,"",-1) -> 1.1523 | H68: =B68/$G68 -> 2241342.7 | I68: =C68/$G68 -> 506396.14 | J68: =H68+I68 -> 2747738.8 | L68: 202509 | M68: 2178650.9 | N68: 14899411 | O68: 4406228.1 | Q68: 21484290 | S68: =J68+N68+O68 -> 22053378
A69: 202510 | B69: 1403619.5 | C69: 409370.19 | D69: 1812989.7 | F69: =F68+7 -> 45993 | G69: =_xlfn.XLOOKUP(F69,FX!$A$12:$A$910,FX!$B$12:$B$910,"",-1) -> 1.1441 | H69: =B69/$G69 -> 1226832.9 | I69: =C69/$G69 -> 357809.8 | J69: =H69+I69 -> 1584642.7 | L69: 202510 | M69: 1990049.5 | N69: 7773847.3 | O69: 2675191.4 | Q69: 12439088 | S69: =J69+N69+O69 -> 12033681
A70: 202511 | B70: 649380.37 | C70: 188367.93 | D70: 837748.29 | F70: =F69+7 -> 46000 | G70: =_xlfn.XLOOKUP(F70,FX!$A$12:$A$910,FX!$B$12:$B$910,"",-1) -> 1.148 | H70: =B70/$G70 -> 565662.34 | I70: =C70/$G70 -> 164083.56 | J70: =H70+I70 -> 729745.9 | L70: 202511 | M70: 567432.92 | N70: 3704503.5 | O70: 921785.43 | Q70: 5193721.8 | S70: =J70+N70+O70 -> 5356034.8
A71: 202512 | B71: 680450.66 | C71: 113963.64 | D71: 794414.3 | F71: =F70+7 -> 46007 | G71: =_xlfn.XLOOKUP(F71,FX!$A$12:$A$910,FX!$B$12:$B$910,"",-1) -> 1.1483 | H71: =B71/$G71 -> 592572.2 | I71: =C71/$G71 -> 99245.529 | J71: =H71+I71 -> 691817.73 | L71: 202512 | M71: 244618.06 | N71: 3559268.9 | O71: 618084.33 | Q71: 4421971.3 | S71: =J71+N71+O71 -> 4869171
... A150: 202639 | B150: 1373417.9 | C150: 271063.35 | D150: 1644481.3 | F150: =F149+7 -> 46560 | G150: =_xlfn.XLOOKUP(F150,FX!$A$12:$A$910,FX!$B$12:$B$910,"",-1) -> 1.198 | H150: =B150/$G150 -> 1146425.6 | I150: =C150/$G150 -> 226263.23 | J150: =H150+I150 -> 1372688.9 | L150: 202639 | M150: 1357184.6 | N150: 8581746.6 | O150: 1584192.6 | Q150: 11523124 | S150: =J150+N150+O150 -> 11538628
A151: 202640 | B151: 0 | C151: 0 | D151: 0 | G151: =_xlfn.XLOOKUP(F151,FX!$A$12:$A$910,FX!$B$12:$B$910,"",-1) -> 1.198 | H151: =B151/$G151 -> 0 | I151: =C151/$G151 -> 0 | J151: =H151+I151 -> 0 | L151: 202640 | M151: 0 | N151: 0 | O151: 0 | Q151: 0 | S151: =J151+N151+O151 -> 0
A152: 202641 | B152: 0 | C152: 0 | D152: 0 | G152: =_xlfn.XLOOKUP(F152,FX!$A$12:$A$910,FX!$B$12:$B$910,"",-1) -> 1.198 | H152: =B152/$G152 -> 0 | I152: =C152/$G152 -> 0 | J152: =H152+I152 -> 0 | L152: 202641 | M152: 0 | N152: 0 | O152: 0 | Q152: 0 | S152: =J152+N152+O152 -> 0
A153: 202642 | B153: 0 | C153: 0 | D153: 0 | G153: =_xlfn.XLOOKUP(F153,FX!$A$12:$A$910,FX!$B$12:$B$910,"",-1) -> 1.198 | H153: =B153/$G153 -> 0 | I153: =C153/$G153 -> 0 | J153: =H153+I153 -> 0 | L153: 202642 | M153: 0 | N153: 0 | O153: 0 | Q153: 0 | S153: =J153+N153+O153 -> 0
A154: 202643 | B154: 0 | C154: 0 | D154: 0 | G154: =_xlfn.XLOOKUP(F154,FX!$A$12:$A$910,FX!$B$12:$B$910,"",-1) -> 1.198 | H154: =B154/$G154 -> 0 | I154: =C154/$G154 -> 0 | J154: =H154+I154 -> 0 | L154: 202643 | M154: 0 | N154: 0 | O154: 0 | Q154: 0 | S154: =J154+N154+O154 -> 0
A155: 202644 | B155: 0 | C155: 0 | D155: 0 | G155: =_xlfn.XLOOKUP(F155,FX!$A$12:$A$910,FX!$B$12:$B$910,"",-1) -> 1.198 | H155: =B155/$G155 -> 0 | I155: =C155/$G155 -> 0 | J155: =H155+I155 -> 0 | L155: 202644 | M155: 0 | N155: 0 | O155: 0 | Q155: 0 | S155: =J155+N155+O155 -> 0
A156: 202645 | B156: 0 | C156: 0 | D156: 0 | G156: =_xlfn.XLOOKUP(F156,FX!$A$12:$A$910,FX!$B$12:$B$910,"",-1) -> 1.198 | H156: =B156/$G156 -> 0 | I156: =C156/$G156 -> 0 | J156: =H156+I156 -> 0 | L156: 202645 | M156: 0 | N156: 0 | O156: 0 | Q156: 0 | S156: =J156+N156+O156 -> 0
A157: 202646 | B157: 0 | C157: 0 | D157: 0 | G157: =_xlfn.XLOOKUP(F157,FX!$A$12:$A$910,FX!$B$12:$B$910,"",-1) -> 1.198 | H157: =B157/$G157 -> 0 | I157: =C157/$G157 -> 0 | J157: =H157+I157 -> 0 | L157: 202646 | M157: 0 | N157: 0 | O157: 0 | Q157: 0 | S157: =J157+N157+O157 -> 0
...

Sheet Sheet9

Sheet Sheet8
A2: TimePeriod | B2: WEEK
A3: Fin_Period | B3: (Multiple Items)
A4: Branch_Type | B4: Company
A5: Division | B5: Furniture
B7: Country | C7: Values
B8: AU | D8: NZ
A9: Channel | B9: R-ASP TY | C9: R-ATV TY | D9: R-ASP TY | E9: R-ATV TY
A10: Dropship | B10: 339.04354 | C10: 510.00027
A11: In Store | B11: 715.5094 | C11: 1731.772 | D11: 727.87475 | E11: 1693.2142
A12: Online | B12: 702.19854 | C12: 1273.5617 | D12: 750.16011 | E12: 1304.176
A13: Grand Total | B13: 629.33768 | C13: 1305.6201 | D13: 730.81687 | E13: 1627.4266

Sheet Sheet6
A1: TimePeriod | B1: WEEK | I1: TimePeriod | J1: WEEK
A2: Branch_Type | B2: Company | I2: Branch_Type | J2: Company
A3: Division | B3: (Multiple Items) | I3: Division | J3: (Multiple Items)
A4: Country | B4: AU | I4: Country | J4: AU
A6: R-Sales TY $ | B6: Channel | I6: R-Sales TY $ | J6: Channel
A7: Fin_Period | B7: Dropship | C7: In Store | D7: Online | F7: Grand Total | I7: Fin_Period | J7: Dropship | K7: In Store | L7: Online | N7: Grand Total
A8: 202401 | B8: 376905.36 | C8: 6851992.3 | D8: 2155136.6 | E8: 0 | F8: 9384034.2 | I8: 202401 | J8: 376905.36 | K8: 6851992.3 | L8: 2155136.6 | M8: 0 | N8: 9384034.2
A9: 202402 | B9: 138197.55 | C9: 3523042.4 | D9: 487672.03 | E9: 0 | F9: 4148912 | I9: 202402 | J9: 138197.55 | K9: 3523042.4 | L9: 487672.03 | M9: 0 | N9: 4148912
A10: 202403 | B10: 141073.46 | C10: 3877218.2 | D10: 622969.5 | E10: 0 | F10: 4641261.1 | I10: 202403 | J10: 141073.46 | K10: 3877218.2 | L10: 622969.5 | M10: 0 | N10: 4641261.1
A11: 202404 | B11: 242571.17 | C11: 5286957.8 | D11: 843955.33 | E11: 0 | F11: 6373484.3 | I11: 202404 | J11: 242571.17 | K11: 5286957.8 | L11: 843955.33 | M11: 0 | N11: 6373484.3
A12: 202405 | B12: 268468.51 | C12: 5772565.3 | D12: 1136353.3 | E12: 0 | F12: 7177387.1 | I12: 202405 | J12: 268468.51 | K12: 5772565.3 | L12: 1136353.3 | M12: 0 | N12: 7177387.1
A13: 202406 | B13: 349721.11 | C13: 5676214.2 | D13: 1094373.2 | E13: 0 | F13: 7120308.5 | I13: 202406 | J13: 349721.11 | K13: 5676214.2 | L13: 1094373.2 | M13: 0 | N13: 7120308.5
A14: 202407 | B14: 265584.27 | C14: 4320967.4 | D14: 869353.63 | E14: 0 | F14: 5455905.3 | I14: 202407 | J14: 265584.27 | K14: 4320967.4 | L14: 869353.63 | M14: 0 | N14: 5455905.3
A15: 202408 | B15: 370461.47 | C15: 12389582 | D15: 3860922.4 | E15: 0 | F15: 16620965 | I15: 202408 | J15: 370461.47 | K15: 12389582 | L15: 3860922.4 | M15: 0 | N15: 16620965
A16: 202409 | B16: 303091.63 | C16: 6005461.4 | D16: 2231137.4 | E16: 0 | F16: 8539690.5 | I16: 202409 | J16: 303091.63 | K16: 6005461.4 | L16: 2231137.4 | M16: 0 | N16: 8539690.5
A17: 202410 | B17: 145182.65 | C17: 3073912.9 | D17: 601991.76 | E17: 0 | F17: 3821087.3 | I17: 202410 | J17: 145182.65 | K17: 3073912.9 | L17: 601991.76 | M17: 0 | N17: 3821087.3
A18: 202411 | B18: 136993.8 | C18: 3264059.8 | D18: 586222.72 | E18: 0 | F18: 3987276.3 | I18: 202411 | J18: 136993.8 | K18: 3264059.8 | L18: 586222.72 | M18: 0 | N18: 3987276.3
A19: 202412 | B19: 172183.66 | C19: 4131597.5 | D19: 883862.86 | E19: 0 | F19: 5187644 | I19: 202412 | J19: 172183.66 | K19: 4131597.5 | L19: 883862.86 | M19: 0 | N19: 5187644
... A59: 202452 | B59: 411074.67 | C59: 3998323.6 | D59: 572565.54 | E59: 0 | F59: 4981963.8 | I59: 202452 | J59: 411074.67 | K59: 3998323.6 | L59: 572565.54 | M59: 0 | N59: 4981963.8
A60: 202501 | B60: 431537.96 | C60: 4388629.3 | D60: 660083.6 | F60: 5480250.9 | I60: 202501 | J60: 431537.96 | K60: 4388629.3 | L60: 660083.6 | N60: 5480250.9
A61: 202502 | B61: 496870.92 | C61: 4583915.1 | D61: 864820.33 | F61: 5945606.4 | I61: 202502 | J61: 496870.92 | K61: 4583915.1 | L61: 864820.33 | N61: 5945606.4
A62: 202503 | B62: 382413.25 | C62: 3952360.6 | D62: 734055.84 | F62: 5068829.7 | I62: 202503 | J62: 382413.25 | K62: 3952360.6 | L62: 734055.84 | N62: 5068829.7
A63: 202504 | B63: 695779.86 | C63: 6951189.2 | D63: 1422808.7 | F63: 9069777.8 | I63: 202504 | J63: 695779.86 | K63: 6951189.2 | L63: 1422808.7 | N63: 9069777.8
A64: 202505 | B64: 533868.95 | C64: 4886511.6 | D64: 1208223.4 | F64: 6628604 | I64: 202505 | J64: 533868.95 | K64: 4886511.6 | L64: 1208223.4 | N64: 6628604
A65: 202506 | B65: 552401.85 | C65: 4722660.4 | D65: 929385.23 | F65: 6204447.5 | I65: 202506 | J65: 552401.85 | K65: 4722660.4 | L65: 929385.23 | N65: 6204447.5
A66: 202507 | B66: 698777.42 | C66: 4453606.6 | D66: 811783.19 | F66: 5964167.2 | I66: 202507 | J66: 698777.42 | K66: 4453606.6 | L66: 811783.19 | N66: 5964167.2
A67: 202508 | B67: 755703.23 | C67: 4768905.4 | D67: 910188.72 | F67: 6434797.3 | I67: 202508 | J67: 755703.23 | K67: 4768905.4 | L67: 910188.72 | N67: 6434797.3
A68: 202509 | B68: 2178650.9 | C68: 14899411 | D68: 4406228.1 | F68: 21484290 | I68: 202509 | J68: 2178650.9 | K68: 14899411 | L68: 4406228.1 | N68: 21484290
A69: 202510 | B69: 1990049.5 | C69: 7773847.3 | D69: 2675191.4 | F69: 12439088 | I69: 202510 | J69: 1990049.5 | K69: 7773847.3 | L69: 2675191.4 | N69: 12439088
A70: 202511 | B70: 567432.92 | C70: 3704503.5 | D70: 921785.43 | F70: 5193721.8 | I70: 202511 | J70: 567432.92 | K70: 3704503.5 | L70: 921785.43 | N70: 5193721.8
A71: 202512 | B71: 244618.06 | C71: 3559268.9 | D71: 618084.33 | F71: 4421971.3 | I71: 202512 | J71: 244618.06 | K71: 3559268.9 | L71: 618084.33 | N71: 4421971.3
... A215: 202752 | B215: 0 | C215: 0 | D215: 0 | F215: 0 | I215: 202752 | J215: 0 | K215: 0 | L215: 0 | N215: 0
A216: Grand Total | B216: 97904078 | C216: 7.6089579e+08 | D216: 1.5751306e+08 | E216: 0 | F216: 1.0163129e+09 | I216: Grand Total | J216: 97904078 | K216: 7.6089579e+08 | L216: 1.5751306e+08 | M216: 0 | N216: 1.0163129e+09

Sheet Sheet5
A2: TimePeriod | B2: WEEK
A3: Branch_Type | B3: Company
A4: Division | B4: (Multiple Items)
A5: Fin_Period | B5: (Multiple Items)
A7: R-Sales TY $ | B7: Channel
A8: Country | B8: Dropship | C8: In Store | D8: Online | E8: Grand Total | F8: AUD
A9: AU | B9: 21816207 | C9: 1.2199822e+08 | D9: 28667703 | E9: 1.7248213e+08 | F9: 1.7248213e+08
A10: NZ | C10: 25000155 | D10: 5061993.1 | E10: 30062148 | F10: =GETPIVOTDATA("[Measures].[R-Sales TY $]",$A$7,"[BI vw_WeeklyWrittenSalesMetrics].[Country]","[BI vw_WeeklyWrittenSalesMetrics].[Country].&[NZ]")/1.1 -> 27329225
A11: Grand Total | B11: 21816207 | C11: 1.4699837e+08 | D11: 33729696 | E11: 2.0254427e+08 | F11: =SUM(F9:F10) -> 1.9981135e+08

Sheet Sheet4
C1: TimePeriod | D1: WEEK
C2: Branch_Type | D2: Company
C3: Division | D3: (Multiple Items)
C4: Country | D4: AU
C5: Store_Name | D5: VIC Nunawading
C7: R-Sales TY $ | D7: Channel | K7: Vic Nunawading
C8: Fin_Period | D8: Dropship | E8: In Store | F8: Online | G8: Grand Total | K8: Month | L8: Total Sales
B9: 45870 | C9: 202544 | D9: 11779.009 | E9: 85238.109 | F9: 15191.056 | G9: 112208.17 | K9: 45870 | L9: 161671.75
B10: 45870 | C10: 202545 | D10: 6830.2364 | E10: 122903.48 | F10: 9252.9199 | G10: 138986.64 | K10: 45901 | L10: 752244.38
B11: 45870 | C11: 202546 | D11: 7305.7001 | E11: 104497.65 | F11: 15159.078 | G11: 126962.43 | K11: 45931 | L11: 620191.75
B12: 45870 | C12: 202547 | D12: 46283.827 | E12: 68822.455 | F12: 46565.47 | G12: 161671.75 | K12: 45962 | L12: 514096.98
B13: Sep | C13: 202548 | D13: 8029.0452 | E13: 59885.532 | F13: 15549.774 | G13: 83464.352 | K13: 45992 | L13: 1114204.4
B14: Sep | C14: 202549 | D14: 32348.309 | E14: 169715.53 | F14: 44159.69 | G14: 246223.53 | K14: 46023 | L14: 666203.42
B15: Sep | C15: 202550 | D15: 19845.455 | E15: 111555.19 | F15: 24627.152 | G15: 156027.8 | K15: 46054 | L15: 559150.8
B16: Sep | C16: 202551 | D16: 13073.955 | E16: 98804.668 | F16: 9149.1615 | G16: 121027.78 | K16: 46082 | L16: 682537.61
B17: Sep | C17: 202552 | D17: 11977.009 | E17: 117433.19 | F17: 16090.717 | G17: 145500.91 | K17: 46113 | L17: 449745.85
B18: Oct | C18: 202601 | D18: 20644.863 | E18: 91935.787 | F18: 12703.451 | G18: 125284.1 | K18: 46143 | L18: 758523.09
B19: Oct | C19: 202602 | D19: 10283.873 | E19: 95108.671 | F19: 5873.422 | G19: 111265.97 | K19: 46174 | L19: 1299094.7
B20: Oct | C20: 202603 | D20: 12163.227 | E20: 134524.19 | F20: 30564.993 | G20: 177252.41 | K20: 46204 | L20: 788387.94
B21: Oct | C21: 202604 | D21: 27882.345 | E21: 140572.42 | F21: 37934.503 | G21: 206389.27 | L21: =SUM(L9:L20) -> 8366052.6
B22: Nov | C22: 202605 | D22: 9919.7726 | E22: 79608.563 | F22: 17399.83 | G22: 106928.17
B23: Nov | C23: 202606 | D23: 12072.2 | E23: 121501.25 | F23: 21829.243 | G23: 155402.69
B24: Nov | C24: 202607 | D24: 24800.846 | E24: 89091.655 | F24: 13086.164 | G24: 126978.66
B25: Nov | C25: 202608 | D25: 24971.1 | E25: 93164.722 | F25: 6651.63 | G25: 124787.45
B26: Dec | C26: 202609 | D26: 76511.901 | E26: 301120.66 | F26: 83890.946 | G26: 461523.5
B27: Dec | C27: 202610 | D27: 54936.336 | E27: 110184.43 | F27: 31147.345 | G27: 196268.11
B28: Dec | C28: 202611 | D28: 21740.409 | E28: 40953.159 | F28: 16187.142 | G28: 78880.711
B29: Dec | C29: 202612 | D29: 13539.682 | E29: 60035.967 | F29: 10896.826 | G29: 84472.475
B30: Dec | C30: 202613 | D30: 26819.782 | E30: 241954.75 | F30: 24285.026 | G30: 293059.56
B31: Jan | C31: 202614 | D31: 32272.792 | E31: 117048.1 | F31: 23922.556 | G31: 173243.45
B32: Jan | C32: 202615 | D32: 16463.318 | E32: 78199.159 | F32: 17909.124 | G32: 112571.6
B33: Jan | C33: 202616 | D33: 23409.382 | E33: 107551.97 | F33: 15662.043 | G33: 146623.39
... B63: Aug | C63: 202707 | D63: 27978.973 | E63: 81845.636 | F63: 18187.189 | G63: 128011.8
C64: Grand Total | D64: 1323279.4 | E64: 6736761.6 | F64: 1069061.5 | G64: 9129102.4

Sheet Sheet1
A1: TimePeriod | B1: WEEK | L1: TimePeriod | M1: WEEK
A2: Branch_Type | B2: Company | L2: Branch_Type | M2: Company
A3: Division | B3: (Multiple Items) | L3: Division | M3: (Multiple Items)
A4: Country | B4: NZ | L4: Country | M4: AU
A6: R-GM$ TY | B6: Channel | F6: NZ (AUD) | L6: R-Sales TY $ | M6: Channel
A7: Fin_Period | B7: In Store | C7: Online | D7: Grand Total | F7: Date week | G7: FX Rate (A$1=NZD) | H7: Instore | I7: Online | J7: Total | L7: Fin_Period | M7: Dropship | N7: In Store | O7: Online | Q7: Grand Total
A8: 202401 | B8: 449418.31 | C8: 84414.81 | D8: 533833.12 | F8: 45566 | G8: =_xlfn.XLOOKUP(F8,FX!$A$12:$A$910,FX!$B$12:$B$910,"",-1) -> 1.0938 | H8: =B8/$G8 -> 410877.96 | I8: =C8/$G8 -> 77175.727 | J8: =H8+I8 -> 488053.68 | L8: 202401 | M8: 376905.36 | N8: 6851992.3 | O8: 2155136.6 | P8: 0 | Q8: 9384034.2 | S8: =J8+N8+O8 -> 9495182.5
A9: 202402 | B9: 452263.18 | C9: 84382.45 | D9: 536645.63 | F9: =F8+7 -> 45573 | G9: =_xlfn.XLOOKUP(F9,FX!$A$12:$A$910,FX!$B$12:$B$910,"",-1) -> 1.1001 | H9: =B9/$G9 -> 411110.97 | I9: =C9/$G9 -> 76704.345 | J9: =H9+I9 -> 487815.32 | L9: 202402 | M9: 138197.55 | N9: 3523042.4 | O9: 487672.03 | P9: 0 | Q9: 4148912 | S9: =J9+N9+O9 -> 4498529.8
A10: 202403 | B10: 747928.14 | C10: 327598.93 | D10: 1075527.1 | F10: =F9+7 -> 45580 | G10: =_xlfn.XLOOKUP(F10,FX!$A$12:$A$910,FX!$B$12:$B$910,"",-1) -> 1.1031 | H10: =B10/$G10 -> 678023.88 | I10: =C10/$G10 -> 296980.26 | J10: =H10+I10 -> 975004.14 | L10: 202403 | M10: 141073.46 | N10: 3877218.2 | O10: 622969.5 | P10: 0 | Q10: 4641261.1 | S10: =J10+N10+O10 -> 5475191.8
A11: 202404 | B11: 604926.28 | C11: 106588.89 | D11: 711515.17 | F11: =F10+7 -> 45587 | G11: =_xlfn.XLOOKUP(F11,FX!$A$12:$A$910,FX!$B$12:$B$910,"",-1) -> 1.104 | H11: =B11/$G11 -> 547940.47 | I11: =C11/$G11 -> 96547.908 | J11: =H11+I11 -> 644488.38 | L11: 202404 | M11: 242571.17 | N11: 5286957.8 | O11: 843955.33 | P11: 0 | Q11: 6373484.3 | S11: =J11+N11+O11 -> 6775401.5
A12: 202405 | B12: 629937.2 | C12: 86147.43 | D12: 716084.63 | F12: =F11+7 -> 45594 | G12: =_xlfn.XLOOKUP(F12,FX!$A$12:$A$910,FX!$B$12:$B$910,"",-1) -> 1.0993 | H12: =B12/$G12 -> 573034.84 | I12: =C12/$G12 -> 78365.715 | J12: =H12+I12 -> 651400.55 | L12: 202405 | M12: 268468.51 | N12: 5772565.3 | O12: 1136353.3 | P12: 0 | Q12: 7177387.1 | S12: =J12+N12+O12 -> 7560319.2
A13: 202406 | B13: 601120.71 | C13: 145547.02 | D13: 746667.73 | F13: =F12+7 -> 45601 | G13: =_xlfn.XLOOKUP(F13,FX!$A$12:$A$910,FX!$B$12:$B$910,"",-1) -> 1.103 | H13: =B13/$G13 -> 544987.04 | I13: =C13/$G13 -> 131955.59 | J13: =H13+I13 -> 676942.64 | L13: 202406 | M13: 349721.11 | N13: 5676214.2 | O13: 1094373.2 | P13: 0 | Q13: 7120308.5 | S13: =J13+N13+O13 -> 7447530
A14: 202407 | B14: 530865.18 | C14: 138868.77 | D14: 669733.95 | F14: =F13+7 -> 45608 | G14: =_xlfn.XLOOKUP(F14,FX!$A$12:$A$910,FX!$B$12:$B$910,"",-1) -> 1.1 | H14: =B14/$G14 -> 482604.71 | I14: =C14/$G14 -> 126244.34 | J14: =H14+I14 -> 608849.05 | L14: 202407 | M14: 265584.27 | N14: 4320967.4 | O14: 869353.63 | P14: 0 | Q14: 5455905.3 | S14: =J14+N14+O14 -> 5799170.1
A15: 202408 | B15: 1276747.3 | C15: 509594.13 | D15: 1786341.4 | F15: =F14+7 -> 45615 | G15: =_xlfn.XLOOKUP(F15,FX!$A$12:$A$910,FX!$B$12:$B$910,"",-1) -> 1.1055 | H15: =B15/$G15 -> 1154904.8 | I15: =C15/$G15 -> 460962.58 | J15: =H15+I15 -> 1615867.4 | L15: 202408 | M15: 370461.47 | N15: 12389582 | O15: 3860922.4 | P15: 0 | Q15: 16620965 | S15: =J15+N15+O15 -> 17866371
A16: 202409 | B16: 677160.61 | C16: 263829.11 | D16: 940989.72 | F16: =F15+7 -> 45622 | G16: =_xlfn.XLOOKUP(F16,FX!$A$12:$A$910,FX!$B$12:$B$910,"",-1) -> 1.1116 | H16: =B16/$G16 -> 609176.51 | I16: =C16/$G16 -> 237341.77 | J16: =H16+I16 -> 846518.28 | L16: 202409 | M16: 303091.63 | N16: 6005461.4 | O16: 2231137.4 | P16: 0 | Q16: 8539690.5 | S16: =J16+N16+O16 -> 9083117.2
A17: 202410 | B17: 263973.52 | C17: 91179.69 | D17: 355153.21 | F17: =F16+7 -> 45629 | G17: =_xlfn.XLOOKUP(F17,FX!$A$12:$A$910,FX!$B$12:$B$910,"",-1) -> 1.1011 | H17: =B17/$G17 -> 239736.19 | I17: =C17/$G17 -> 82807.819 | J17: =H17+I17 -> 322544.01 | L17: 202410 | M17: 145182.65 | N17: 3073912.9 | O17: 601991.76 | P17: 0 | Q17: 3821087.3 | S17: =J17+N17+O17 -> 3998448.7
A18: 202411 | B18: 342785.71 | C18: 88524.96 | D18: 431310.67 | F18: =F17+7 -> 45636 | G18: =_xlfn.XLOOKUP(F18,FX!$A$12:$A$910,FX!$B$12:$B$910,"",-1) -> 1.0958 | H18: =B18/$G18 -> 312817.77 | I18: =C18/$G18 -> 80785.691 | J18: =H18+I18 -> 393603.46 | L18: 202411 | M18: 136993.8 | N18: 3264059.8 | O18: 586222.72 | P18: 0 | Q18: 3987276.3 | S18: =J18+N18+O18 -> 4243885.9
A19: 202412 | B19: 466152.08 | C19: 85906.28 | D19: 552058.36 | F19: =F18+7 -> 45643 | G19: =_xlfn.XLOOKUP(F19,FX!$A$12:$A$910,FX!$B$12:$B$910,"",-1) -> 1.1018 | H19: =B19/$G19 -> 423082.3 | I19: =C19/$G19 -> 77969.032 | J19: =H19+I19 -> 501051.33 | L19: 202412 | M19: 172183.66 | N19: 4131597.5 | O19: 883862.86 | P19: 0 | Q19: 5187644 | S19: =J19+N19+O19 -> 5516511.6
A20: 202413 | B20: 825694.37 | C20: 214736.72 | D20: 1040431.1 | F20: =F19+7 -> 45650 | G20: =_xlfn.XLOOKUP(F20,FX!$A$12:$A$910,FX!$B$12:$B$910,"",-1) -> 1.1054 | H20: =B20/$G20 -> 746964.33 | I20: =C20/$G20 -> 194261.55 | J20: =H20+I20 -> 941225.88 | L20: 202413 | M20: 472899.16 | N20: 9467931.7 | O20: 2540040.2 | P20: 0 | Q20: 12480871 | S20: =J20+N20+O20 -> 12949198
... A35: 202428 | B35: 329567.6 | C35: 76036.62 | D35: 405604.22 | F35: =F34+7 -> 45755 | G35: =_xlfn.XLOOKUP(F35,FX!$A$12:$A$910,FX!$B$12:$B$910,"",-1) -> 1.0822 | H35: =B35/$G35 -> 304534.84 | I35: =C35/$G35 -> 70261.153 | J35: =H35+I35 -> 374795.99 | L35: 202428 | M35: 235413.91 | N35: 3722821.6 | O35: 641555.64 | P35: 0 | Q35: 4599791.2 | S35: =J35+N35+O35 -> 4739173.2
A36: 202429 | B36: 473137.64 | C36: 50905.22 | D36: 524042.86 | F36: =F35+7 -> 45762 | G36: =_xlfn.XLOOKUP(F36,FX!$A$12:$A$910,FX!$B$12:$B$910,"",-1) -> 1.0753 | H36: =B36/$G36 -> 440005.25 | I36: =C36/$G36 -> 47340.482 | J36: =H36+I36 -> 487345.73 | L36: 202429 | M36: 290838.8 | N36: 4399442.9 | O36: 540104.21 | P36: 0 | Q36: 5230385.9 | S36: =J36+N36+O36 -> 5426892.8 | AB36: DS GM
A37: 202430 | B37: 553805.45 | C37: 126846.41 | D37: 680651.86 | F37: =F36+7 -> 45769 | G37: =_xlfn.XLOOKUP(F37,FX!$A$12:$A$910,FX!$B$12:$B$910,"",-1) -> 1.0684 | H37: =B37/$G37 -> 518350.29 | I37: =C37/$G37 -> 118725.58 | J37: =H37+I37 -> 637075.87 | L37: 202430 | M37: 333149.16 | N37: 4339266.1 | O37: 873560.87 | P37: 0 | Q37: 5545976.2 | S37: =J37+N37+O37 -> 5849902.9
A38: 202431 | B38: 563953.74 | C38: 87578.95 | D38: 651532.69 | F38: =F37+7 -> 45776 | G38: =_xlfn.XLOOKUP(F38,FX!$A$12:$A$910,FX!$B$12:$B$910,"",-1) -> 1.0769 | H38: =B38/$G38 -> 523682.55 | I38: =C38/$G38 -> 81325.053 | J38: =H38+I38 -> 605007.61 | L38: 202431 | M38: 261632.54 | N38: 5537169.5 | O38: 806753.4 | P38: 0 | Q38: 6605555.5 | S38: =J38+N38+O38 -> 6948930.5 | X38: April | Y38: 480308.59 | AA38: April | AB38: =+SUMIF(X38:X50,AA38,Y38:Y50) -> 2403988.7
A39: 202432 | B39: 348916.81 | C39: 54005.05 | D39: 402921.86 | F39: =F38+7 -> 45783 | G39: =_xlfn.XLOOKUP(F39,FX!$A$12:$A$910,FX!$B$12:$B$910,"",-1) -> 1.0805 | H39: =B39/$G39 -> 322921.62 | I39: =C39/$G39 -> 49981.536 | J39: =H39+I39 -> 372903.16 | L39: 202432 | M39: 235949.9 | N39: 3145647.1 | O39: 426337.72 | P39: 0 | Q39: 3807934.7 | S39: =J39+N39+O39 -> 3944887.9 | X39: April | Y39: 411064.82 | AA39: May | AB39: =+SUMIF(X39:X51,AA39,Y39:Y51) -> 1889610.7
A40: 202433 | B40: 484528.45 | C40: 93071.97 | D40: 577600.42 | F40: =F39+7 -> 45790 | G40: =_xlfn.XLOOKUP(F40,FX!$A$12:$A$910,FX!$B$12:$B$910,"",-1) -> 1.0885 | H40: =B40/$G40 -> 445134.08 | I40: =C40/$G40 -> 85504.796 | J40: =H40+I40 -> 530638.88 | L40: 202433 | M40: 304883.73 | N40: 4896887.7 | O40: 947471.02 | P40: 0 | Q40: 6149242.4 | S40: =J40+N40+O40 -> 6374997.6 | X40: April | Y40: 797063.31 | AA40: June | AB40: =+SUMIF(X40:X52,AA40,Y40:Y52) -> 1345942.5
A41: 202434 | B41: 708642.7 | C41: 192122.88 | D41: 900765.58 | F41: =F40+7 -> 45797 | G41: =_xlfn.XLOOKUP(F41,FX!$A$12:$A$910,FX!$B$12:$B$910,"",-1) -> 1.0843 | H41: =B41/$G41 -> 653548.56 | I41: =C41/$G41 -> 177186.09 | J41: =H41+I41 -> 830734.65 | L41: 202434 | M41: 603104.63 | N41: 7462656.6 | O41: 1991408.8 | P41: 0 | Q41: 10057170 | S41: =J41+N41+O41 -> 10284800 | X41: April | Y41: 715551.98
A42: 202435 | B42: 640641.98 | C42: 156507.3 | D42: 797149.28 | F42: =F41+7 -> 45804 | G42: =_xlfn.XLOOKUP(F42,FX!$A$12:$A$910,FX!$B$12:$B$910,"",-1) -> 1.0834 | H42: =B42/$G42 -> 591325.44 | I42: =C42/$G42 -> 144459.39 | J42: =H42+I42 -> 735784.83 | L42: 202435 | M42: 486831.2 | N42: 6435460.9 | O42: 1495992.5 | P42: 0 | Q42: 8418284.6 | S42: =J42+N42+O42 -> 8667238.2 | X42: May | Y42: 535441.37
A43: 202436 | B43: 672126.44 | C43: 162590.38 | D43: 834716.82 | F43: =F42+7 -> 45811 | G43: =_xlfn.XLOOKUP(F43,FX!$A$12:$A$910,FX!$B$12:$B$910,"",-1) -> 1.0757 | H43: =B43/$G43 -> 624827.03 | I43: =C43/$G43 -> 151148.44 | J43: =H43+I43 -> 775975.48 | L43: 202436 | M43: 407979.28 | N43: 6182961.5 | O43: 1120879.3 | P43: 0 | Q43: 7711820.1 | S43: =J43+N43+O43 -> 8079816.3 | X43: May | Y43: 329496.46
A44: 202437 | B44: 516153.3 | C44: 127323.98 | D44: 643477.28 | F44: =F43+7 -> 45818 | G44: =_xlfn.XLOOKUP(F44,FX!$A$12:$A$910,FX!$B$12:$B$910,"",-1) -> 1.0763 | H44: =B44/$G44 -> 479562.67 | I44: =C44/$G44 -> 118297.85 | J44: =H44+I44 -> 597860.52 | L44: 202437 | M44: 389434.5 | N44: 6934444.3 | O44: 1238711.8 | P44: 0 | Q44: 8562590.6 | S44: =J44+N44+O44 -> 8771016.6 | X44: May | Y44: 351697.1
A45: 202438 | B45: 623042.99 | C45: 107113.75 | D45: 730156.74 | F45: =F44+7 -> 45825 | G45: =_xlfn.XLOOKUP(F45,FX!$A$12:$A$910,FX!$B$12:$B$910,"",-1) -> 1.0772 | H45: =B45/$G45 -> 578391.19 | I45: =C45/$G45 -> 99437.198 | J45: =H45+I45 -> 677828.39 | L45: 202438 | M45: 445573.06 | N45: 7611533.9 | O45: 1469795.1 | P45: 0 | Q45: 9526902.1 | S45: =J45+N45+O45 -> 9759157.4 | X45: May | Y45: 335148.32
A46: 202439 | B46: 970069.68 | C46: 181801.02 | D46: 1151870.7 | F46: =F45+7 -> 45832 | G46: =_xlfn.XLOOKUP(F46,FX!$A$12:$A$910,FX!$B$12:$B$910,"",-1) -> 1.0805 | H46: =B46/$G46 -> 897797.02 | I46: =C46/$G46 -> 168256.38 | J46: =H46+I46 -> 1066053.4 | L46: 202439 | M46: 879734.1 | N46: 13298213 | O46: 2880357.3 | P46: 0 | Q46: 17058305 | S46: =J46+N46+O46 -> 17244624 | X46: June | Y46: 345281.99
A47: 202440 | B47: 416537.42 | C47: 100748.73 | D47: 517286.15 | F47: =F46+7 -> 45839 | G47: =_xlfn.XLOOKUP(F47,FX!$A$12:$A$910,FX!$B$12:$B$910,"",-1) -> 1.0787 | H47: =B47/$G47 -> 386147.6 | I47: =C47/$G47 -> 93398.285 | J47: =H47+I47 -> 479545.89 | L47: 202440 | M47: 480308.59 | N47: 4374888.3 | O47: 946826.04 | P47: 0 | Q47: 5802022.9 | S47: =J47+N47+O47 -> 5801260.2 | X47: June | Y47: 284390.62
A48: 202441 | B48: 261927.13 | C48: 35610.42 | D48: 297537.55 | F48: =F47+7 -> 45846 | G48: =_xlfn.XLOOKUP(F48,FX!$A$12:$A$910,FX!$B$12:$B$910,"",-1) -> 1.0869 | H48: =B48/$G48 -> 240985.49 | I48: =C48/$G48 -> 32763.29 | J48: =H48+I48 -> 273748.78 | L48: 202441 | M48: 411064.82 | N48: 3212266.4 | O48: 438706.33 | P48: 0 | Q48: 4062037.6 | S48: =J48+N48+O48 -> 3924721.6 | X48: June | Y48: 305195.25
A49: 202442 | B49: 463701.33 | C49: 109149.03 | D49: 572850.36 | F49: =F48+7 -> 45853 | G49: =_xlfn.XLOOKUP(F49,FX!$A$12:$A$910,FX!$B$12:$B$910,"",-1) -> 1.0956 | H49: =B49/$G49 -> 423239.62 | I49: =C49/$G49 -> 99624.89 | J49: =H49+I49 -> 522864.51 | L49: 202442 | M49: 797063.31 | N49: 4937921.7 | O49: 1076143.2 | P49: 0 | Q49: 6811128.2 | S49: =J49+N49+O49 -> 6536929.4 | X49: May | Y49: 337827.48
A50: 202443 | B50: 409968.17 | C50: 101260.96 | D50: 511229.13 | F50: =F49+7 -> 45860 | G50: =_xlfn.XLOOKUP(F50,FX!$A$12:$A$910,FX!$B$12:$B$910,"",-1) -> 1.0944 | H50: =B50/$G50 -> 374605.42 | I50: =C50/$G50 -> 92526.462 | J50: =H50+I50 -> 467131.88 | L50: 202443 | M50: 715551.98 | N50: 4730578.8 | O50: 986634.29 | P50: 0 | Q50: 6432765 | S50: =J50+N50+O50 -> 6184344.9 | X50: June | Y50: 411074.67
A51: 202444 | B51: 420490.66 | C51: 80332.55 | D51: 500823.21 | F51: =F50+7 -> 45867 | G51: =_xlfn.XLOOKUP(F51,FX!$A$12:$A$910,FX!$B$12:$B$910,"",-1) -> 1.093 | H51: =B51/$G51 -> 384712.41 | I51: =C51/$G51 -> 73497.301 | J51: =H51+I51 -> 458209.71 | L51: 202444 | M51: 535441.37 | N51: 4662371.2 | O51: 677002.17 | P51: 0 | Q51: 5874814.8 | S51: =J51+N51+O51 -> 5797583.1
A52: 202445 | B52: 500590.92 | C52: 44629.97 | D52: 545220.89 | F52: =F51+7 -> 45874 | G52: =_xlfn.XLOOKUP(F52,FX!$A$12:$A$910,FX!$B$12:$B$910,"",-1) -> 1.0957 | H52: =B52/$G52 -> 456868.6 | I52: =C52/$G52 -> 40731.925 | J52: =H52+I52 -> 497600.52 | L52: 202445 | M52: 329496.46 | N52: 5115734.5 | O52: 860692.68 | P52: 0 | Q52: 6305923.6 | S52: =J52+N52+O52 -> 6474027.7
A53: 202446 | B53: 309187.49 | C53: 57165.95 | D53: 366353.44 | F53: =F52+7 -> 45881 | G53: =_xlfn.XLOOKUP(F53,FX!$A$12:$A$910,FX!$B$12:$B$910,"",-1) -> 1.0958 | H53: =B53/$G53 -> 282156.86 | I53: =C53/$G53 -> 52168.233 | J53: =H53+I53 -> 334325.1 | L53: 202446 | M53: 351697.1 | N53: 3387789.9 | O53: 722741.7 | P53: 0 | Q53: 4462228.7 | S53: =J53+N53+O53 -> 4444856.7
A54: 202447 | B54: 383841.06 | C54: 68478.06 | D54: 452319.12 | F54: =F53+7 -> 45888 | G54: =_xlfn.XLOOKUP(F54,FX!$A$12:$A$910,FX!$B$12:$B$910,"",-1) -> 1.095 | H54: =B54/$G54 -> 350539.78 | I54: =C54/$G54 -> 62537.041 | J54: =H54+I54 -> 413076.82 | L54: 202447 | M54: 335148.32 | N54: 3838227.4 | O54: 630649.43 | P54: 0 | Q54: 4804025.2 | S54: =J54+N54+O54 -> 4881953.7
A55: 202448 | B55: 459508.46 | C55: 75687.54 | D55: 535196 | F55: =F54+7 -> 45895 | G55: =_xlfn.XLOOKUP(F55,FX!$A$12:$A$910,FX!$B$12:$B$910,"",-1) -> 1.1096 | H55: =B55/$G55 -> 414120.82 | I55: =C55/$G55 -> 68211.554 | J55: =H55+I55 -> 482332.37 | L55: 202448 | M55: 345281.99 | N55: 4637103 | O55: 691745.58 | P55: 0 | Q55: 5674130.6 | S55: =J55+N55+O55 -> 5811180.9
...

Sheet Sheet3
B1: Fin_Period | C1: Dropship | D1: In Store | E1: Online | F1: Total | G1: DS Mix | H1: DS Mix (13wk avg)
B2: 202401 | C2: 376905.36 | D2: 6851992.3 | E2: 2155136.6 | F2: =SUM(C2:E2) -> 9384034.2 | G2: =C2/F2 -> 0.040164534
B3: 202402 | C3: 138197.55 | D3: 3523042.4 | E3: 487672.03 | F3: =SUM(C3:E3) -> 4148912 | G3: =C3/F3 -> 0.033309346
B4: 202403 | C4: 141073.46 | D4: 3877218.2 | E4: 622969.5 | F4: =SUM(C4:E4) -> 4641261.1 | G4: =C4/F4 -> 0.030395502
B5: 202404 | C5: 242571.17 | D5: 5286957.8 | E5: 843955.33 | F5: =SUM(C5:E5) -> 6373484.3 | G5: =C5/F5 -> 0.038059429
B6: 202405 | C6: 268468.51 | D6: 5772565.3 | E6: 1136353.3 | F6: =SUM(C6:E6) -> 7177387.1 | G6: =C6/F6 -> 0.037404769
B7: 202406 | C7: 349721.11 | D7: 5676214.2 | E7: 1094373.2 | F7: =SUM(C7:E7) -> 7120308.5 | G7: =C7/F7 -> 0.049116005
B8: 202407 | C8: 265584.27 | D8: 4320967.4 | E8: 869353.63 | F8: =SUM(C8:E8) -> 5455905.3 | G8: =C8/F8 -> 0.048678314
B9: 202408 | C9: 370461.47 | D9: 12389582 | E9: 3860922.4 | F9: =SUM(C9:E9) -> 16620965 | G9: =C9/F9 -> 0.022288806
B10: 202409 | C10: 303091.63 | D10: 6005461.4 | E10: 2231137.4 | F10: =SUM(C10:E10) -> 8539690.5 | G10: =C10/F10 -> 0.035492109
B11: 202410 | C11: 145182.65 | D11: 3073912.9 | E11: 601991.76 | F11: =SUM(C11:E11) -> 3821087.3 | G11: =C11/F11 -> 0.037995115
B12: 202411 | C12: 136993.8 | D12: 3264059.8 | E12: 586222.72 | F12: =SUM(C12:E12) -> 3987276.3 | G12: =C12/F12 -> 0.034357739
B13: 202412 | C13: 172183.66 | D13: 4131597.5 | E13: 883862.86 | F13: =SUM(C13:E13) -> 5187644 | G13: =C13/F13 -> 0.03319111
B14: 202413 | C14: 472899.16 | D14: 9467931.7 | E14: 2540040.2 | F14: =SUM(C14:E14) -> 12480871 | G14: =C14/F14 -> 0.037889916 | H14: =AVERAGE(G2:G14) -> 0.036795592
B15: 202414 | C15: 239614.3 | D15: 6514097.2 | E15: 1270652 | F15: =SUM(C15:E15) -> 8024363.5 | G15: =C15/F15 -> 0.029860848 | H15: =AVERAGE(G3:G15) -> 0.036003001
B16: 202415 | C16: 248546.66 | D16: 5866689.6 | E16: 1148658.4 | F16: =SUM(C16:E16) -> 7263894.6 | G16: =C16/F16 -> 0.034216722 | H16: =AVERAGE(G4:G16) -> 0.036072799
B17: 202416 | C17: 235754.62 | D17: 5354661 | E17: 909050.65 | F17: =SUM(C17:E17) -> 6499466.2 | G17: =C17/F17 -> 0.03627292 | H17: =AVERAGE(G5:G17) -> 0.036524908
B18: 202417 | C18: 432990.33 | D18: 8756099.5 | E18: 1579864.7 | F18: =SUM(C18:E18) -> 10768955 | G18: =C18/F18 -> 0.040207276 | H18: =AVERAGE(G6:G18) -> 0.036690127
